Workbook

Sheet Read me
A1: The lists workbook
A2: Everything the Substrate still needs decided. One tab per list. Source of truth: docs/dictionary.md Part 11.
A4: How to use this
A5: Yellow cells are yours to fill. | B5: Every tab has one grey italic example row showing the expected format. Delete it or leave it — it is ignored.
A6: Grey italic row = example. | B6: It is not data. It shows the shape of an entry.
A7: Fill in the order on the right. | B7: Not tab order. The order is a dependency order, and getting it wrong wastes work.
A8: A list is done when you would bet a year on it. | B8: These cannot be revised once a Campaign exists. That is the whole reason they are being written down before any code.
A10: The order to fill them in
A11: # | B11: List | C11: Why here
A12: 1 | B12: L29 Capacities | C12: The most load-bearing list. What a character is made of AND the axes an attempt splits across.
A13: 2 | B13: L21 Dimension Spaces | C13: Then L22 Dimensions, then L23 Channels. Strictly in that order.
A14: 3 | B14: L22 Dimensions, per Space
A15: 4 | B15: L23 Named Channels
A16: 5 | B16: L27 Sockets | C16: Blocks the Component contract.
A17: 6 | B17: L28 Economy Units | C17: Blocks every spell and ability ever written.
A18: 7 | B18: L1 / L2 / L3 | C18: Categories, then Universal Attributes, then Category Attributes.
A19: 8 | B19: L4 Tags and L5 State axes
A20: 9 | B20: L18 Aggregation operators | C20: The single most likely source of a determinism bug.
A21: 10 | B21: L25 Conversions | C21: What a surviving vector actually does.
A22: 11 | B22: L7 Layers — the rest | C22: Everything outside resolution: progression, economy, movement, knowledge, standing.
A23: 12 | B23: L26 Listener conditions | C23: Plus the cascade limit and the evaluation order.
A24: 13 | B24: L6 VERBS — LAST | C24: Not third, and not an afternoon. Every list above produces the evidence.
A26: Status key
A27: BLOCKING | B27: Nothing can be built until this is done.
A28: PENDING | B28: Needed, not yet blocking anything.
A29: PARTIAL | B29: Shape decided, contents open.
A30: CLOSE LAST | B30: Deliberately not settled yet. Settling it early is the mistake.
A32: HOW TO USE THE PROPOSALS — added August 2026
A34: Every blocking tab now opens with PROPOSED rows on a pale yellow background. They are a starting position, not an answer.
A35: Three things to do with each row: accept it, edit it, or cut it. Cutting is the most valuable of the three.
A37: When you cut one, move it down to the CONSIDERED AND REJECTED block on the same tab and say why. Nothing above the
A38: Substrate can put back something the Substrate omitted, and in two years you will not remember whether a thing is missing
A39: because you decided against it or because you never thought of it.
A41: THE ORDER, and it matters — each list needs the one before it:
A42: L21 Spaces → L29 Capacities → L22 Dimensions → L23 Channels → L27 Sockets / L28 Economy Units
A43: → L1 / L2 / L3 (+ the three character sheets) → L4 / L5 / L18 / L25 → L7 Layers → L26 Listeners → L6 VERBS LAST
A45: L21 before L29 looks backwards and is not: the Capacities ARE the Dimensions of the attempt Space, so the Space has to
A46: exist first. Deciding Spaces is coarse and quick; deciding Capacities is not.
A48: L6 Verbs is closed LAST, always. It is the one genuinely irreversible decision, and the evidence for its completeness is
... A69: tell you what each has to carry.

Sheet Progress
A1: Progress
A2: Rows filled per list. Counts any row below the example with something in the first column.
A4: List | B4: Status | C4: Rows filled | D4: Done?
A5: L1 · Categories | B5: PENDING · BLOCKING | C5: =COUNTA('L1 Categories'!A8:A47) | D5: =IF(C5>0,"started","not started")
A6: L2 · Universal Attributes | B6: PENDING · BLOCKING | C6: =COUNTA('L2 Universal Attributes'!A8:A47) | D6: =IF(C6>0,"started","not started")
A7: L3 · Category Attributes | B7: PENDING · BLOCKING | C7: =COUNTA('L3 Category Attributes'!A8:A47) | D7: =IF(C7>0,"started","not started")
A8: L4 · Core Tag vocabulary | B8: PENDING · BLOCKING | C8: =COUNTA('L4 Core Tag vocabulary'!A8:A47) | D8: =IF(C8>0,"started","not started")
A9: L5 · State axes | B9: PENDING · BLOCKING | C9: =COUNTA('L5 State axes'!A8:A47) | D9: =IF(C9>0,"started","not started")
A10: L6 · Verbs | B10: PRELIMINARY · CLOSE LAST | C10: =COUNTA('L6 Verbs'!A8:A47) | D10: =IF(C10>0,"started","not started")
A11: L7 · Layers | B11: PARTIAL · BLOCKING | C11: =COUNTA('L7 Layers'!A8:A47) | D11: =IF(C11>0,"started","not started")
A12: L10 · Challenge Profile axes | B12: PENDING | C12: =COUNTA('L10 Challenge Profile axes'!A8:A47) | D12: =IF(C12>0,"started","not started")
A13: L11 · Asset types | B13: PENDING | C13: =COUNTA('L11 Asset types'!A8:A47) | D13: =IF(C13>0,"started","not started")
A14: L12 · Rails binding scopes | B14: PENDING | C14: =COUNTA('L12 Rails binding scopes'!A8:A47) | D14: =IF(C14>0,"started","not started")
A15: L13 · Record types | B15: PENDING | C15: =COUNTA('L13 Record types'!A8:A47) | D15: =IF(C15>0,"started","not started")
A16: L18 · Aggregation operators | B16: PENDING · BLOCKING | C16: =COUNTA('L18 Aggregation operators'!A8:A47) | D16: =IF(C16>0,"started","not started")
A17: L19 · Causal tag vocabulary | B17: PENDING | C17: =COUNTA('L19 Causal tag vocabulary'!A8:A47) | D17: =IF(C17>0,"started","not started")
A18: L20 · Lens tiers | B18: PENDING | C18: =COUNTA('L20 Lens tiers'!A8:A47) | D18: =IF(C18>0,"started","not started")
A19: L21 · Dimension Spaces | B19: SETTLED · Aug 2026 | C19: =COUNTA('L21 Dimension Spaces'!A8:A47) | D19: =IF(C19>0,"started","not started")
A20: L22 · Dimensions, per Space | B20: SETTLED · Aug 2026 | C20: =COUNTA('L22 Dimensions, per Space'!A8:A47) | D20: =IF(C20>0,"started","not started")
A21: L23 · Named Channels | B21: SETTLED · Aug 2026 | C21: =COUNTA('L23 Named Channels'!A8:A47) | D21: =IF(C21>0,"started","not started")
A22: L24 · Guard presets | B22: PENDING | C22: =COUNTA('L24 Guard presets'!A8:A47) | D22: =IF(C22>0,"started","not started")
A23: L25 · Transient-to-Persistent conversions | B23: PENDING · BLOCKING | C23: =COUNTA('L25 Transient-to-Persistent con'!A8:A47) | D23: =IF(C23>0,"started","not started")
A24: L26 · Listener condition forms | B24: PENDING | C24: =COUNTA('L26 Listener condition forms'!A8:A47) | D24: =IF(C24>0,"started","not started")
A25: L27 · Sockets | B25: SHAPE SETTLED · three · Aug 2026 | C25: =COUNTA('L27 Sockets'!A8:A47) | D25: =IF(C25>0,"started","not started")
A26: L28 · Economy | B26: SETTLED IN PRINCIPLE · Aug 2026 | C26: =COUNTA('L28 Economy'!A8:A47) | D26: =IF(C26>0,"started","not started")
A27: L29 · Attempt Domains & Dimensions | B27: SETTLED · Aug 2026 | C27: =COUNTA('L29 Capacities'!A8:A47) | D27: =IF(C27>0,"started","not started")
A28: L30 · Instrumentation surfaces | B28: PENDING | C28: =COUNTA('L30 Instrumentation surfaces'!A8:A47) | D28: =IF(C28>0,"started","not started")
A29: L31 · Timings | B29: PENDING · BLOCKING · NEXT | C29: =COUNTA('L31 Timings'!A8:A47) | D29: =IF(C29>0,"started","not started")
A30: L32 · Moment kinds | B30: PENDING · BLOCKING · NEXT | C30: =COUNTA('L32 Moment kinds'!A8:A47) | D30: =IF(C30>0,"started","not started")
A32: Total | B32: =SUM(C5:C30)
A34: Blocking lists started | B34: =COUNTIFS(B5:B30,"*BLOCKING*",C5:C30,">0")
A35: Blocking lists total | B35: =COUNTIF(B5:B30,"*BLOCKING*")
A36: Settled | B36: =COUNTIF(B5:B30,"*SETTLED*")

Sheet L1 Categories
A1: L1 · Categories
A2: PENDING · BLOCKING · research-seeded Aug 2026
A3: The labels an Entity may carry saying what kind of thing it is. An Entity may carry several at once; each brings its own Attributes.
A4: A CATEGORY THAT BRINGS NO ATTRIBUTES IS A TAG. The boundary the whole field draws: exactly one value true and values partition → Category. Any number true at once, minted forever → Tag. One true within an axis, started and ended by a Verb → State.
A6: Category | B6: What it is | C6: Attributes it adds | D6: Can it ATTEMPT? | E6: Notes
A7: haunted | B7: a place with a ghost | C7: none | D7: — | E7: NOT a Category — a Tag. It adds nothing to the sheet. | F7: ← example, not data
A8: Being | B8: Anything with a body and agency | C8: the attempt Dimensions, the physical/mental Dimensions | D8: yes — nothing gates it | E8: The only Category nobody argues about.
A9: Object | B9: A made or found thing | C9: physical Dimensions, Mass/Bulk/Hardness | D9: yes — nothing gates it | E9: "Can be targeted" without "can attempt" is the test that separates L2 from L3.
A10: Place | B10: A location that can contain things | C10: containment, Scale | D10: yes — nothing gates it | E10: Overlaps the Place Socket. Argue whether this is a Category at all or purely Socket business.
A11: Group | B11: A faction, crew, guild, household | C11: social Dimensions, standing | D11: yes — nothing gates it | E11: Reign's companies act like characters. Star Trek Adventures' ships do NOT act — they assist. See notes below.
A12: Relationship | B12: A Category of Entity holding one CONNECTION per participant | C12: one stance per participant, stored independently | D12: yes — nothing gates it | E12: NEVER an edge. 4 of 5 surveyed systems agree (Exalted Intimacies, DG Bonds, Cortex relationship dice, Monsterhearts strings). Blades faction status is an edge, and Blades' faction game is the part most often houseruled.
A13: Knowledge | B13: A rumour, a secret, a piece of lore | C13: provenance, spread | D13: yes — nothing gates it | E13: The hardest test case for L2 — a rumour has almost no attributes.
A14: Phenomenon | B14: A storm, a fire, a plague | C14: physical Dimensions, Scale | D14: yes — nothing gates it | E14: ATTACK THIS ONE FIRST — it may just be an Object with Tags.
A15: Proposal | B15: A pending decision awaiting a Decider | C15: decider, Moment, default | D15: yes — nothing gates it | E15: Ours, not the field's. Rule 21: a human Decider always carries a Moment and a default.
A16: Vector | B16: A pending push not yet resolved | C16: direction, magnitude, pin, layer | D16: yes — nothing gates it | E16: Ours. Already an Entity by the dictionary.
A18: SETTLED Aug 2026: ANYTHING MAY ATTEMPT. No Category gates it. An Entity with no points in any attempt Dimension simply cannot attempt — 'absent is not zero' already said so, and adding a gate would enforce for free what the open-world reading enforces anyway. Star Trek Adventures' stance (the ship ASSISTS, it never rolls) stays available as CONTENT: a Setting that wants it simply gives ships no attempt Dimensions.
A20: CONSIDERED AND REJECTED
A21: Ship / Vehicle | E21: ARGUE: is this a Category, or an Object with a Group aboard? Traveller, Lancer and Scum & Villainy all give ships their own sheet; STA gives them the SAME six attributes as characters, deliberately.
A22: Character / NPC | E22: REJECT as separate Categories — both are Being. The distinction is a Lens concern.
A23: Item / Weapon / Armour | E23: REJECT: all Object. The differences are Tags and Facets.

Sheet L2 Universal Attributes
A1: L2 · Universal Attributes
A2: PENDING · BLOCKING · research-seeded Aug 2026
A3: What EVERY Entity has. Test each candidate against a rumour, a lock, a faction and a storm. If any of those does not need it, it is a Category Attribute and belongs in L3.
A4: L2 SHOULD BE BRUTALLY SHORT — four or five entries. The shortness IS the evidence the model is not a person schema in a costume. If it grows, L29 needs redoing.
A6: Candidate | B6: rumour | C6: lock | D6: faction | E6: storm | F6: Verdict and notes
A7: hit points | B7: no | C7: maybe | D7: no | E7: no | F7: NOT universal, and not even shipped — the Substrate ships no Resources. | G7: ← example, not data
A8: identity (permanent ID) | B8: yes | C8: yes | D8: yes | E8: yes | F8: UNIVERSAL. Numeric, permanent, never reused.
A9: Category | B9: yes | C9: yes | D9: yes | E9: yes | F9: UNIVERSAL. Multi-select.
A10: Tags | B10: yes | C10: yes | D10: yes | E10: yes | F10: UNIVERSAL. Open, optional magnitude.
A11: Scale | B11: yes | C11: yes | D11: yes | E11: yes | F11: UNIVERSAL — and Scale belongs to PARTS as well as wholes. A Scale-4 ship has Scale-1 doors.
A12: Facets | B12: yes | C12: yes | D12: yes | E12: yes | F12: UNIVERSAL, but it is structure rather than an attribute. Argue whether it belongs on this list at all.
A13: Place / containment reference | B13: stretch | C13: yes | D13: stretch | E13: yes | F13: ARGUE. A rumour's "place" is where it is believed; a faction's is its turf. Both are real and both are stretched.
A14: the 14 non-attempt Dimensions | B14: stretch | C14: yes | D14: yes | E14: yes | F14: ARGUE. A rumour has no temperature — but "absent is not zero" already covers that, so the cost of including them may be zero.
A15: the 15 attempt Dimensions | B15: no | C15: no | D15: maybe | E15: no | F15: NOT UNIVERSAL → L3. A building never attempts a grapple; a Relationship never rolls.
A17: PERSON-ASSUMPTIONS THAT LEAK MOST OFTEN, from the survey: initiative (a rumour does not act) · carrying capacity (a faction does not carry) · movement speed (a lock does not move) · level and advancement (a storm does not learn) · hit points.
A19: CONSIDERED AND REJECTED
A20: name | F20: ARGUE: is a display name Substrate, or a Lens concern? A pending vector has no name anyone says out loud.
A21: owner | F21: REJECT: that is a Relationship.
A22: initiative | F22: REJECT: person-assumption, and turn order is base Ruleset.

Sheet L3 Category Attributes
A1: L3 · Category Attributes
A2: PENDING · BLOCKING
A3: What each Category adds. Fill after L1 and L2.
A4: NOW SEEDABLE — the Dimensions tell you what each Category needs to carry. An Attribute here is what a FORMULA reads to produce a Dimension value or a Threshold.
A6: Category (L1) | B6: Attribute | C6: Type | D6: Default | E6: Why this Category needs it
A7: person | B7: allocation points | C7: whole number | D7: TBD | E7: How finely they can split attention | F7: ← example, not data
A8: being | B8: vitality pool | C8: integer Resource | D8: 0 | E8: vitality landings need somewhere to go
A9: being | B9: vigor pool | C9: integer Resource | D9: 0 | E9: exhaustion needs somewhere to go
A10: being | B10: the three mental pools | C10: integer Resources | D10: 0 | E10: composure, clarity, will landings
A11: being | B11: reach / stride | C11: integer | D11: 0 | E11: feeds mobility
A12: object | B12: integrity pool | C12: integer Resource | D12: 0
A13: object | B13: substance pool | C13: integer Resource | D13: 0
A14: structure | B14: parts | C14: list of Entity ids | D14: empty | E14: each part carries its own Scale and Thresholds
A15: place | B15: scope | C15: Place Socket vocabulary | D15: — | E15: what "here" and "near" mean is the Place Socket's job
A16: place | B16: connections | C16: list of place ids | D16: empty
A17: group | B17: membership | C17: list of Entity ids | D17: empty
A18: group | B18: cohesion | C18: integer Resource | D18: 0 | E18: the group's equivalent of integrity
A19: relationship | B19: connections | C19: one Connection per participant | D19: — | E19: each stance stored INDEPENDENTLY. Never an edge
A20: information | B20: truth | C20: boolean or graded | D20: unknown | E20: a rumour can be false and still spread
A21: occasion | B21: when | C21: a Moment | D21: —
A23: THE OVERLAP TEST: if the same word means the same thing on two Categories, define it once at the most general Category that needs it.

Sheet L4 Core Tag vocabulary
A1: L4 · Core Tag vocabulary
A2: PENDING · BLOCKING · research-seeded Aug 2026
A3: The seed vocabulary Components may rely on existing. Open cluster membership, optional magnitude, identified by ID not name, NEVER implies another Tag.
A4: THE NUMBER THAT MATTERS: Magic published 222 keywords in 33 years and keeps ~17 ALWAYS-LIVE. No cap on the total; a hard cap around 15–20 on the always-on set. Path of Exile runs 46 simultaneously live tags and they are that game's most notorious confusion.
A6: Tag | B6: Kind | C6: Tier | D6: What it is for | E6: Notes
A7: Humanoid | B7: membership only | C7: — | D7: what kind of creature | E7: NOT a Tag — a CATEGORY. One value true, values partition. PF2e files Goblin as a trait and pays for it with three unrelated meanings on one name. | F7: ← example, not data
A8: Mass | B8: magnitude: fixed-point | C8: Substrate | D8: Thresholds and Guards read it; the number IS the meaning | E8: Never a Capacity — it is not a disposition
A9: Bulk | B9: magnitude: integer | C9: Substrate | D9: What a container's Capacity consumes | E9: Distinct from Mass: bulky-but-light is real
A10: Hardness | B10: magnitude: integer | C10: Substrate | D10: The classic flat-Guard input at R-850 | E10: Membership alone is meaningless
A11: Reach | B11: magnitude: distance | C11: Substrate | D11: A Threshold on engagement | E11: PF2e Reach 15 feet · Lancer Threat
A12: Multiplicity | B12: magnitude: whole count | C12: Substrate | D12: Number of identical constituent parts | E12: Feeds integer apportionment. Not a Resource — not depletable by the Substrate
A13: Reliability | B13: magnitude: integer | C13: Ruleset | D13: A guaranteed floor on a vector's magnitude | E13: Lancer Reliable X — the one directly transplantable Lancer tag
A14: Volatility | B14: magnitude: integer | C14: Ruleset | D14: How much disturbance releases stored energy | E14: Graded because 'somewhat volatile' is a real thing
A15: Signature | B15: magnitude: integer | C15: Ruleset | D15: How detectable — a Threshold contributor | E15: Replaces a dozen Setting-specific stealth flags
A16: Illumination | B16: magnitude: integer | C16: Ruleset | D16: Emitted light as a Threshold contributor | E16: Candle vs beacon: the number matters
A17: Manufactured | B17: membership only | C17: Substrate | D17: Made by an agent rather than occurring | E17: The most-referenced predicate in every ruleset
A18: Portable | B18: membership only | C18: Substrate | D18: Can be carried by one participant at its own Scale
A19: Anchored | B19: membership only | C19: Substrate | D19: Fixed to a Place | E19: NOT the negation of Portable — a thing can be neither
A20: Container | B20: membership only | C20: Substrate | D20: Has interior capacity that can hold other Entities | E20: Referenced by Place logic
A21: Consumable | B21: membership only | C21: Substrate | D21: Expended by use | E21: Not a Resource — the label the Resource system keys on
A22: Unique | B22: membership only | C22: Substrate | D22: Exactly one instance may exist in a Campaign | E22: Pure authoring key, zero resolution meaning — proves the shape is supported
A23: Living | B23: membership only | C23: Ruleset | E23: Deliberately implies NOTHING. 'Living therefore breathes' must place Respiring too
A24: Sapient | B24: membership only | C24: Ruleset | E24: Never implies Living — constructs, spirits
A25: Metallic | B25: membership only | C25: Ruleset
A26: Mineral | B26: membership only | C26: Ruleset | E26: Co-holdable with Metallic
A27: Organic | B27: membership only | C27: Ruleset | E27: Co-holdable with Manufactured — leather armour
A28: Fibrous | B28: membership only | C28: Ruleset | E28: Small but heavily referenced; cheap to ship
A29: Flammable | B29: membership only | C29: Ruleset | E29: EXPLICITLY not derived from Organic. That derivation is the hierarchy being forbidden
A30: Conductive | B30: membership only | C30: Ruleset | E30: EXPLICITLY not derived from Metallic
A31: Porous | B31: membership only | C31: Ruleset | E31: Gates a large class of Component effects
A33: TARGET: 11 in the Substrate seed, ~24 across the base Ruleset, then Components publish forever. ONLY MINT A TAG WHEN SOMETHING ELSE MUST REFERENCE IT — if no Modifier, Guard, Threshold or Listener will ever key on the cluster, it is documentation, not a Tag, and should not consume an ID.
A35: CONSIDERED AND REJECTED
A36: tag hierarchy / inheritance | D36: REJECT, and it is the best-supported rule in the whole set. MTG surgically REMOVED its last implication (Wall meaning "can't attack") and errata'd thousands of cards rather than keep it. PF2e Goblin softly implies darkvision and every consumer special-cases it. PoE Righteous Fire carries Spell and AoE tags and NEITHER spell nor area modifiers affect it — ten years of documented confusion.
A37: derivation at read time | D37: THE GATE THAT IS MISSING. A Component computing "if hasTag(Metallic) then treatAs(Conductive)" has reintroduced hierarchy in BEHAVIOUR while passing the schema check. CI must forbid any Tag ID appearing in the definition or resolution predicate of another Tag, and the Fold must never synthesise membership.
A38: optional magnitude per instance | D38: ARGUE — PROPOSED CHANGE. Make it declared PER TAG, permanently from mint: "carries no magnitude" or "carries a magnitude in unit U". Optional per instance means every reader writes if(magnitude !== undefined), which turns "absent is not zero" into a per-call-site judgement. Lancer: 19 of 67 tags carry a value, and the value TYPE varies per tag — Reliable is a floor, Blast a radius, Overkill a DIE FACE. Nothing generic can be written over "the magnitude."
A39: fire, cold, lightning | D39: REJECT: those are Channel positions over Dimensions, not Tags.
A40: creature kinds (Undead, Beast) | D40: REJECT: Categories by the cardinality test.

Sheet L5 State axes
A1: L5 · State axes
A2: PENDING · BLOCKING · research-seeded Aug 2026
A3: The shape, not the contents. What axes the base Ruleset ships, and what fields a State definition carries. Most States live in Components.
A4: THE DECISION IS AXES, NOT CONDITIONS. The test: can two members be true at once? If yes, they are two axes, or they are Tags.
A6: Axis | B6: Members (illustrative — Components fill these) | C6: Genuinely exclusive? | D6: Notes | E6: Precedent
A7: poisoned | B7: — | C7: no | D7: NOT an axis — you can be poisoned and prone and blind. That is a State on its own axis, or a Resource. | E7: 5e poisoned | F7: ← example, not data
A8: posture | B8: standing · prone · seated · airborne | C8: yes | D8: You cannot be both prone and airborne | E8: 5e prone · WFRP Prone
A9: restraint | B9: free · grabbed · restrained · immobilised | C9: yes | D9: PF2e and 5e both treat these as a ladder | E9: 5e grappled/restrained · Lancer Immobilized
A10: consciousness | B10: awake · asleep · unconscious | C10: yes | E10: 5e unconscious · WFRP
A11: awareness | B11: aware · surprised · unaware | C11: yes | E11: 5e surprised · PF2e
A12: visibility | B12: seen · concealed · hidden · unseen | C12: yes | D12: PF2e's four-step ladder is the best-specified version in print | E12: PF2e concealed/hidden/undetected
A13: animacy | B13: living · dying · dead | C13: yes | D13: PF2e dying/wounded is really a track, not a condition — watch for that | E13: PF2e dying + wounded
A14: containment | B14: free · contained · submerged | C14: yes | D14: Overlaps Place; argue whether it belongs to the Place Socket instead | E14: —
A16: FIELDS A STATE DEFINITION CARRIES: name · axis · optional magnitude · optional MAXIMUM · what it does · how it ends. FORGETTING THE MAX IS THE MISTAKE — values add by default, so without a ceiling "poisoned 47" is reachable.
A18: CONSIDERED AND REJECTED
A19: additive magnitudes | D19: REJECT. PF2e takes the HIGHER value when a numeric condition is applied twice, never the sum. Additive stacking makes any repeatable source unbounded. This settles L18: the operator for States is max.
A20: conditions that imply other conditions | D20: REJECT, and it is a live maintenance cost in a shipping product: 5e paralyzed/stunned/unconscious all include incapacitated, and the 2024 revision had to widen incapacitated, which cascaded to all three. Same failure as tag hierarchy.
A21: intrinsic durations (save-ends, N rounds) | D21: ARGUE. 5e conditions have NO intrinsic duration — they end because the effect that imposed them ends, or a named action ends them. That is already our design, validated at the largest scale in the hobby. 4e layered durations on top and the tracking load is its most-cited failure.
A22: a long condition list | D22: 3e/PF1 carried 34+. 4e carried more. 5e cut to 15. NOBODY HAS GROWN A CONDITION LIST AND BEEN GLAD.

Sheet L6 Verbs
A1: L6 · Verbs
A2: PRELIMINARY · CLOSE LAST
A3: The closed set of operations that change state. DO NOT FREEZE THIS UNTIL EVERY OTHER LIST IS DONE.
A4: Closing procedure: run every entry from every other list plus every worked example through this. A consequence needing an operation not here is a real finding; one needing a Tag or Channel is not.
A6: Verb | B6: What changed (never what was done) | C6: Example consequence | D6: Composes from existing? | E6: Keep / cut / undecided
A7: apply | B7: A Packet is delivered to a target | C7: Burning down a warehouse | D7: No — nothing else expresses it | E7: keep | F7: ← example, not data

Sheet L7 Layers
A1: L7 · Layers
A2: PARTIAL · BLOCKING
A3: The precedence lattice. Resolution region is drafted (E-/C-/R-). What is open is everything outside resolution.
A4: REVISED — the resolution region is now THIRTY slots (E×5, C×6, R×19) after Phase 0 and the L21–L23 work. What remains is everything OUTSIDE resolution.
A6: Slot | B6: Region | C6: Name | D6: What belongs here | E6: May depend on (earlier slots only)
A7: R-400 | B7: Resolution | C7: Apply percentage | D7: The one multiplication; truncate toward zero | E7: R-300, R-350 | F7: ← example, not data
A8: E-100 … E-500 | B8: entity | C8: preparing an Entity | D8: existence, Categories, its own numbers, its ceilings | E8: —
A9: C-100 … C-600 | B9: creation | C9: creating a vector | D9: everything the source contributes, collapsed to a direction and four numbers | E9: E-region
A10: R-100 … R-1400 | B10: resolution | C10: resolving at a Moment | D10: gather · ambient · percentages · capacity clamp · apply · absolutes · vector clamp · resolve · SCALE (R-750) · standing cap (R-780, reserved) · combine per source · FLAT GUARDS per source (R-850) · combine across sources (R-1000) · PROPORTIONAL GUARDS (R-1050) · target clamp · land · RESTORE (R-1250) · record · listeners | E10: E and C regions
A12: STILL EMPTY — the regions outside resolution:
A13: ? | B13: progression | C13: how a character changes over time | E13: needs its own region
A14: ? | B14: economy | C14: Budget refresh, upkeep, costs | E14: the A2 upkeep answer lives here
A15: ? | B15: movement | C15: position, travel, pursuit | E15: interacts with the new mobility Dimension
A16: ? | B16: knowledge | C16: what is known, by whom, when | E16: Almanac
A17: ? | B17: social standing | C17: reputation over time, decay | E17: interacts with the new standing Dimension
A19: THE TEST: take a mechanic you want. Write out what must already be settled before it can be computed. If no existing slot supplies it, that is a new slot.
A20: ERR HIGH. Gaps of 100 so 650 can be inserted. An unused slot costs nothing; a missing one is a foundation break.

Sheet L10 Challenge Profile axes
A1: L10 · Challenge Profile axes
A2: PENDING
A3: How demanding an Entity is. A set of rated axes plus a scalar computed from them by an explicit formula. The shape is never the score.
A6: Axis | B6: What it measures | C6: Scale | D6: Weight in the scalar | E6: Notes
A7: durability | B7: How much it absorbs before it stops | C7: 0-10 | D7: TBD | E7: Radar area is order-dependent and quadratic — never use it as the number | F7: ← example, not data

Sheet L11 Asset types
A1: L11 · Asset types
A2: PENDING
A3: Structures describing concrete authorable things, and which get user authoring first.
A4: Every authoring surface is a real unit of work. Authorable types are what let users build without buying.
A6: Asset type | B6: What it is | C6: User-authorable? | D6: Authoring priority | E6: Notes
A7: creature | B7: A statted thing that can act | C7: yes | D7: 1 | E7: Vehicles are items with a Scale and a crew Relationship, not their own type | F7: ← example, not data

Sheet L12 Rails binding scopes
A1: L12 · Rails binding scopes
A2: PENDING
A3: Who sets each Component's dial — the player, the GM, or the table.
A4: Threshold visibility is a built-in GM setting, not a per-Component rail.
A6: Scope | B6: What it means | C6: Example dial | D6: Default | E6: Notes
A7: table | B7: One setting for everyone | C7: Does the app run initiative | D7: GM | E7: Socket occupants have rails too | F7: ← example, not data

Sheet L13 Record types
A1: L13 · Record types
A2: PENDING
A3: The kinds of entry that can appear in the Ledger. A Verb invocation is only one of them.
A4: Non-Verb Records must stay genuinely inert. The moment a 'note' changes state, the determinism argument collapses.
A6: Record type | B6: Changes state? | C6: Payload summary | D6: Delivery default | E6: Notes
A7: gm assertion | B7: no | C7: Free text plus the Entities it concerns | D7: everyone | E7: What lets the system absorb improvisation without understanding it | F7: ← example, not data

Sheet L18 Aggregation operators
A1: L18 · Aggregation operators
A2: PENDING · BLOCKING
A3: How multiple contributions to one value combine. Declared per Noun kind, overridable only from this closed list.
A4: REVISED. Everything on the resolution path is settled; what remains is the other Noun kinds. NOTE: this is a DIFFERENT question from how a THRESHOLD reads multiple contributors (sum / highest / each), which was settled in L29.
A6: Operator | B6: Applies to which Noun kinds | C6: Behaviour | D6: Default for | E6: Notes
A7: max | B7: State | C7: Highest applicable wins | D7: States within an axis | E7: Removes an entire bug class versus sum | F7: ← example, not data
A8: sum | B8: Capacity, Channel values, percentages | C8: add, then clamp | D8: everything on the resolution path | E8: SETTLED in Phase 0. Percentages sum, nothing compounds
A9: max | B9: State magnitude within an axis; Baseline | C9: take the highest | D9: States, Baselines | E9: PROPOSED. Order-free, therefore safe
A10: union | B10: Tag | C10: set union by ID | D10: Tags | E10: PROPOSED. Order-free
A11: clamp | B11: Resource | C11: add, then bound at min and max | D11: Resources | E11: PROPOSED
A12: per-Connection | B12: Relationship | C12: NEVER merge — each participant's stance stands alone | D12: Relationships | E12: PROPOSED. This is why a Relationship is a Category of Entity rather than an edge
A14: THE TEST: apply each operator to the same three inputs in six different orders. Any operator that gives different answers is wrong.
A15: Named in the architecture as the single most likely source of "the same Ledger produced different state".

Sheet L19 Causal tag vocabulary
A1: L19 · Causal tag vocabulary
A2: PENDING
A3: What a Record is ABOUT, in matchable terms, so the Chronicle can curate. Optional additive field.
A4: Downgraded from blocking — do it when the Chronicle is real.
A6: Tag | B6: What it marks | C6: Who sets it | D6: Example | E6: Notes
A7: betrayal | B7: A Relationship broken by the party that benefited | C7: the emitting Component | D7: A vassal switching sides | E7: Records before this exists have no tags, permanently | F7: ← example, not data

Sheet L20 Lens tiers
A1: L20 · Lens tiers
A2: PENDING
A3: How much mechanical detail a Lens exposes.
A6: Tier | B6: What it shows | C6: Dice it declares | D6: Who it is for | E6: Notes
A7: narrative | B7: Outcomes as prose only | C7: none visible | D7: Someone who wants no numbers | E7: Must still be Calibrated to the same magnitude distribution | F7: ← example, not data

Sheet L21 Dimension Spaces
A1: L21 · Dimension Spaces
A2: SETTLED — August 2026
A3: The named sets of Dimensions. Packets in different Spaces NEVER interact — this is the main thing keeping the system comprehensible as it grows.
A4: Do this before L22 and L22 before L23. The attempt Space's Dimensions ARE the Capacities (L29).
A6: Space | B6: What it governs | C6: Dimensions in it (L22) | D6: Interacts with | E6: Notes
A7: physical | B7: Bodily harm and force | C7: thermal, kinetic, vital | D7: nothing | E7: Two Packets in different Spaces never interact at all | F7: ← example, not data
A8: physical | B8: Bodies and matter | C8: thermal, kinetic, vital, corrosive, vigor? | D8: nothing | E8: SETTLED
A9: mental | B9: The inside of one mind | C9: composure, clarity, will? | D9: nothing | E9: SETTLED. Psychic harm is what forced this Space to exist
A10: social | B10: The space BETWEEN minds — standing, trust, obligation | C10: regard, standing? | D10: nothing | E10: SETTLED. resolve moved to mental, which left this clean
A11: mystic | B11: Workings and what unmakes them — magic, ki, mana, cultivation, divinity | C11: working?, essence? | D11: nothing | E11: SETTLED. COUNTERSPELLING is what forced this Space to exist. A working's EFFECTS live in whatever Space they change; the working's own existence lives here
A12: attempt | B12: How well someone did at something | C12: 7 Domains, 15 Dimensions — see L29 | D12: nothing | E12: SETTLED
A13: RULE: a vector's Space is decided by WHAT IT CHANGES, not what caused it.
A14: RULE: a Space limits a VECTOR, never an ABILITY. One ability places as many vectors as it needs.
A15: Adding a Space later is free. Splitting or merging existing ones is an Edition break.
A17: CONSIDERED AND REJECTED
A18: wealth | B18: Money as its own Space | E18: REJECTED: money is a Resource, not a direction. A bribe is a social vector paid for with a Resource
A19: knowledge | B19: Information as its own Space | E19: REJECTED: a Tag or an Almanac entry. Not a push, and it does not cancel
A20: a separate spirit / divine Space | B20: Souls, gods, the beyond | E20: FOLDED INTO MYSTIC. Two Spaces would mean a miracle and a spell could never meet. One Space with Component-supplied Channels lets them.

Sheet L22 Dimensions, per Space
A1: L22 · Dimensions, per Space
A2: SETTLED — August 2026 (amended when L23 exposed the sign problem and two missing axes)
A3: The axes within each Space. Additive-only — a Dimension may be added forever, none removed or redefined.
A4: SIGN CONVENTION: every Dimension is a property of the target. NEGATIVE always means LESS of it — damaged, taken away. POSITIVE always means MORE — restored, given. Two axes are BIPOLAR (temperature, working): displacement either way is what matters.
A6: Space (L21) | B6: Dimension | C6: Positive means | D6: Negative means | E6: Notes
A7: physical | B7: thermal | C7: heat | D7: cold | E7: Unspecified defaults to zero, so adding a Dimension breaks nothing | F7: ← example, not data
A8: physical | B8: temperature | C8: hotter | D8: colder | E8: BIPOLAR — both directions harm. fire and frost, the reference case
A9: physical | B9: integrity | C9: repaired, reinforced | D9: broken by force | E9: a charge meeting a shield wall. Renamed from kinetic: force TAKES integrity
A10: physical | B10: substance | C10: sealed, restored | D10: dissolved, corroded | E10: acid meeting a mending ward. Renamed from corrosive
A11: physical | B11: vitality | C11: healed, cured | D11: wounded, poisoned, diseased | E11: a regeneration aura meeting incoming venom. Renamed from vital
A12: physical | B12: vigor | C12: rested, energised | D12: exhausted, spent | E12: a forced march meeting a stimulant
A13: physical | B13: mobility | C13: hastened, freed | D13: slowed, restrained, rooted | E13: NEW. Slow/haste/entangle/root had no axis at all
A14: physical | B14: acuity | C14: keen, enhanced | D14: blinded, deafened, numbed | E14: NEW. Blind/deafen/numb had no axis at all
A15: mental | B15: composure | C15: steadied, emboldened | D15: shaken, afraid | E15: the bard meeting the dragon
A16: mental | B16: clarity | C16: lucid, sharp | D16: confused, deceived | E16: a clarity effect meeting an illusion
A17: mental | B17: will | C17: your own | D17: dominated, compelled | E17: breaking a charm meeting the charm
A18: social | B18: regard | C18: admired, trusted | D18: despised | E18: praise meeting slander
A19: social | B19: standing | C19: elevated | D19: diminished | E19: vouched for meeting denounced
... A22: attempt | B22: (15 Dimensions in 7 Domains) | C22: did well | D22: did badly | E22: See L29. NOT available to Channels
A24: ASYMMETRY: a MISSING Dimension is recoverable. A Dimension that turns out to be TWO THINGS is not. Err few.
A26: CONSIDERED AND REJECTED
A27: social | B27: trust | E27: HELD BACK: per-pair, so it is a Connection on a Relationship. A social Dimension is broadcast
A28: mystic | B28: corruption / taint | E28: REJECTED: Setting-specific, therefore a Component
A29: physical | B29: piercing | E29: REJECTED: no opposite. It is a Channel positioned mostly on integrity
A30: physical | B30: holy / unholy | E30: REJECTED: its only opposite is itself negated — same axis. And Setting-specific

Sheet L23 Named Channels
A1: L23 · Named Channels
A2: SETTLED — August 2026
A3: Positions in HUNDREDTHS. Every row must sum, in absolute value, to exactly 100 (column R checks it). No two Channels may share a position.
A4: SIGNS: all-negative harms · all-positive helps · mixed is a TRADE. Only humble, menace and enthrall are mixed.
A6: Group | B6: Channel | C6: temperature | D6: integrity | E6: substance | F6: vitality | G6: vigor | H6: mobility | I6: acuity | J6: composure | K6: clarity | L6: will | M6: regard | N6: standing | O6: working | P6: essence | Q6: |sum| = 100?
A7: FORCE & WEAPONS | B7: impact | C7: thermal +1.0 | D7: -100 | E7: transient | F7: Creating a damage type means placing it. Its relationship to every existing type is then already determined | G7: ← example, not data | Q7: =IF(SUMPRODUCT(ABS(C7:P7))=100,"ok","*** FIX ***")
A8: FORCE & WEAPONS | B8: pierce | C8: thermal +1.0 | D8: -80 | E8: transient | F8: -20 | Q8: =IF(SUMPRODUCT(ABS(C8:P8))=100,"ok","*** FIX ***")
A9: FORCE & WEAPONS | B9: rend | C9: thermal −1.0 | D9: -60 | E9: transient | F9: -40 | Q9: =IF(SUMPRODUCT(ABS(C9:P9))=100,"ok","*** FIX ***")
A10: FORCE & WEAPONS | B10: bleed | C10: kinetic +1.0 | D10: -30 | E10: transient | F10: -70 | Q10: =IF(SUMPRODUCT(ABS(C10:P10))=100,"ok","*** FIX ***")
A11: FORCE & WEAPONS | B11: crush | C11: thermal +0.3, kinetic +0.7 | D11: -70 | E11: -30 | F11: PROPOSED. The interior Channel that proves the Space is worth having | Q11: =IF(SUMPRODUCT(ABS(C11:P11))=100,"ok","*** FIX ***")
A12: FORCE & WEAPONS | B12: stagger | C12: vital +1.0 | D12: -50 | E12: persistent | F12: PROPOSED. Persistent — it keeps working | G12: -50 | Q12: =IF(SUMPRODUCT(ABS(C12:P12))=100,"ok","*** FIX ***")
A13: FORCE & WEAPONS | B13: concussion | C13: corrosive +0.7, thermal +0.3 | D13: -50 | E13: persistent | F13: PROPOSED. Second interior Channel | K13: -50 | Q13: =IF(SUMPRODUCT(ABS(C13:P13))=100,"ok","*** FIX ***")
A14: FORCE & WEAPONS | B14: knockdown | C14: thermal +0.6, vital +0.4 | D14: -40 | E14: transient | F14: PROPOSED. Third interior Channel — the target is at least three | H14: -60 | Q14: =IF(SUMPRODUCT(ABS(C14:P14))=100,"ok","*** FIX ***")
A15: ELEMENTS | B15: fire | C15: 100 | D15: 1.0 | E15: transient | F15: PROPOSED. Fear, at the cost of some standing | Q15: =IF(SUMPRODUCT(ABS(C15:P15))=100,"ok","*** FIX ***")
A16: ELEMENTS | B16: frost | C16: -100 | D16: 1.0 | E16: transient | F16: PROPOSED | Q16: =IF(SUMPRODUCT(ABS(C16:P16))=100,"ok","*** FIX ***")
A17: ELEMENTS | B17: lightning | C17: 30 | D17: -70 | Q17: =IF(SUMPRODUCT(ABS(C17:P17))=100,"ok","*** FIX ***")
A18: ELEMENTS | B18: blast | C18: 50 | D18: -50 | Q18: =IF(SUMPRODUCT(ABS(C18:P18))=100,"ok","*** FIX ***")
A19: ELEMENTS | B19: shockwave | D19: -60 | I19: -40 | Q19: =IF(SUMPRODUCT(ABS(C19:P19))=100,"ok","*** FIX ***")
A20: ELEMENTS | B20: acid | E20: -100 | Q20: =IF(SUMPRODUCT(ABS(C20:P20))=100,"ok","*** FIX ***")
A21: ELEMENTS | B21: molten | C21: 50 | E21: -50 | Q21: =IF(SUMPRODUCT(ABS(C21:P21))=100,"ok","*** FIX ***")
A22: ELEMENTS | B22: scald | C22: 60 | F22: -40 | Q22: =IF(SUMPRODUCT(ABS(C22:P22))=100,"ok","*** FIX ***")
A23: ELEMENTS | B23: frostbite | C23: -50 | F23: -50 | Q23: =IF(SUMPRODUCT(ABS(C23:P23))=100,"ok","*** FIX ***")
A24: ELEMENTS | B24: exposure | C24: -40 | G24: -60 | Q24: =IF(SUMPRODUCT(ABS(C24:P24))=100,"ok","*** FIX ***")
A25: ELEMENTS | B25: flash | I25: -70 | K25: -30 | Q25: =IF(SUMPRODUCT(ABS(C25:P25))=100,"ok","*** FIX ***")
A26: AFFLICTION | B26: venom | F26: -70 | K26: -30 | Q26: =IF(SUMPRODUCT(ABS(C26:P26))=100,"ok","*** FIX ***")
A27: AFFLICTION | B27: blight | E27: -50 | F27: -50 | Q27: =IF(SUMPRODUCT(ABS(C27:P27))=100,"ok","*** FIX ***")
A28: AFFLICTION | B28: agony | F28: -50 | K28: -50 | Q28: =IF(SUMPRODUCT(ABS(C28:P28))=100,"ok","*** FIX ***")
A29: AFFLICTION | B29: fatigue | G29: -70 | J29: -30 | Q29: =IF(SUMPRODUCT(ABS(C29:P29))=100,"ok","*** FIX ***")
A30: AFFLICTION | B30: wither | F30: -60 | G30: -40 | Q30: =IF(SUMPRODUCT(ABS(C30:P30))=100,"ok","*** FIX ***")
A31: AFFLICTION | B31: rot | E31: -60 | G31: -40 | Q31: =IF(SUMPRODUCT(ABS(C31:P31))=100,"ok","*** FIX ***")
A32: AFFLICTION | B32: numb | H32: -40 | I32: -60 | Q32: =IF(SUMPRODUCT(ABS(C32:P32))=100,"ok","*** FIX ***")
A33: BINDING & MOVEMENT | B33: slow | H33: -100 | Q33: =IF(SUMPRODUCT(ABS(C33:P33))=100,"ok","*** FIX ***")
A34: BINDING & MOVEMENT | B34: entangle | G34: -30 | H34: -70 | Q34: =IF(SUMPRODUCT(ABS(C34:P34))=100,"ok","*** FIX ***")
A35: BINDING & MOVEMENT | B35: snare | F35: -20 | H35: -80 | Q35: =IF(SUMPRODUCT(ABS(C35:P35))=100,"ok","*** FIX ***")
A36: BINDING & MOVEMENT | B36: cripple | F36: -40 | H36: -60 | Q36: =IF(SUMPRODUCT(ABS(C36:P36))=100,"ok","*** FIX ***")
A37: BINDING & MOVEMENT | B37: pin | D37: -50 | H37: -50 | Q37: =IF(SUMPRODUCT(ABS(C37:P37))=100,"ok","*** FIX ***")
A38: BINDING & MOVEMENT | B38: petrify | D38: 40 | H38: -60 | Q38: =IF(SUMPRODUCT(ABS(C38:P38))=100,"ok","*** FIX ***")
A39: FEAR & MIND | B39: dread | J39: -100 | Q39: =IF(SUMPRODUCT(ABS(C39:P39))=100,"ok","*** FIX ***")
A40: FEAR & MIND | B40: terror | G40: -30 | J40: -70 | Q40: =IF(SUMPRODUCT(ABS(C40:P40))=100,"ok","*** FIX ***")
A41: FEAR & MIND | B41: confusion | K41: -100 | Q41: =IF(SUMPRODUCT(ABS(C41:P41))=100,"ok","*** FIX ***")
...

Sheet L24 Guard presets
A1: L24 · Guard presets
A2: PENDING
A3: Named Guard configurations. Resistance and immunity are presets, not separate mechanisms.
A4: NOW FILLABLE — L22 and L23 settled the axes and the two Guard forms. FLAT acts once per contributing source at R-850, on the packet total WITHIN A SPACE, redistributed. PROPORTIONAL acts once on the combined total at R-1050. Named acts before universal. A universal flat Guard may never be negative.
A6: Preset | B6: Form | C6: Polarity | D6: Value | E6: What it reads as in play
A7: fire immunity | B7: proportional | C7: thermal-positive | D7: 100% | E7: Shrugs off heat, still feels cold | F7: ← example, not data
A8: plate armour | B8: flat, Dimension-named | C8: unpolarised | D8: integrity 3 | E8: stops the first 3 of any blow, per attacker
A9: heavy plate | B9: flat, Dimension-named | C9: unpolarised | D9: integrity 6 | E9: and it is heavy — pair with a mobility penalty
A10: padded | B10: flat, universal within physical | C10: unpolarised | D10: 3 | E10: stops the first 3 of ANY physical packet, including mixed ones
A11: stone hide | B11: proportional | C11: unpolarised | D11: integrity 50% | E11: half of whatever force is left at the end
A12: fire elemental | B12: proportional | C12: POLARISED temperature-positive | D12: 100% | E12: shrugs off heat, still feels cold. The reference case
A13: acid-etched | B13: proportional | C13: POLARISED substance-negative | D13: −50% | E13: a VULNERABILITY — takes 150%. Same mechanism, other sign
A14: iron will | B14: flat, universal within mental | C14: unpolarised | D14: 3 | E14: the mental equivalent of armour. This is what makes mental Guards a real category
A15: warded | B15: proportional | C15: unpolarised | D15: working 50% | E15: half of any working that reaches you
A16: mindless | B16: proportional | C16: unpolarised | D16: composure 100% / clarity 100% / will 100% | E16: a construct. Immunity by having no mind at all
A18: REMEMBER: a Guard reduces toward zero and never past it. A universal flat Guard is universal WITHIN A SPACE — armour must not blunt a hallucination.

Sheet L25 Transient-to-Persistent con
A1: L25 · Transient-to-Persistent conversions
A2: PENDING · BLOCKING · research-seeded Aug 2026
A3: What a vector that survives Guards actually does. This IS the Landing Socket Vocabulary. Fourteen rows, one per non-attempt Dimension.
A4: THE UNIVERSAL ARCHITECTURE IS BUFFER → CONVERT → NAME. Fate, Blades, Lancer, Delta Green, Mouse Guard all do it. So Landing is a PIPELINE SHAPE, not one step — and the buffer belongs to the Component, never the Substrate.
A6: Dimension | B6: Proposed landing model | C6: What it means | D6: Precedent | E6: Notes and hazards
A7: hit points | B7: L1 deplete a pool | C7: subtract and check zero | D7: D&D | E7: NOT assumed. The Substrate ships no Resources; a Setting may legitimately have none. Masks and Mouse Guard are shipping proof. | F7: ← example, not data
A8: temperature (bipolar) | B8: L11 bank + L6 convert | C8: Accumulate a signed heat value; discharge at a bar | D8: Lancer Heat · WFRP Ablaze · Rolemaster Heat/Cold tables | E8: BIPOLAR needs TWO bars, one per sign. No complete precedent exists — Lancer only implements the hot end.
A9: integrity | B9: L1 pool + L6 convert at zero | C9: Pool is a DISPOSABLE buffer; its only durable effect is the conversion | D9: Lancer HP→Structure (HP resets to full) · Mörk Borg 0 HP→d4 Broken | E9: The buffer is not durable state and should not survive a Moment as a Facet.
A10: substance | B10: L8 permanent scalar edit | C10: Matter removed is matter gone; no recovery without an explicit Verb | D10: Twilight 2000 attribute loss · GURPS DR degradation | E10: Needs an explicit restoration path — L8 has no natural inverse.
A11: vitality | B11: L3 bar → named condition, read HIGHEST | C11: A single blow's magnitude, not the sum, decides the wound | D11: GURPS major wound (>HP/2) · Mythras Serious/Major · Ars Magica | E11: Reading HIGHEST *is* the all-in incentive. Pair with a residue accumulator or small hits are worthless.
A12: vigor | B12: L2 track, non-linear boxes | C12: Fatigue is the archetypal graded track | D12: 5e exhaustion · GURPS FP · Ars Magica Fatigue | E12: Non-linear box counts per severity stop minor harm accumulating at the same rate as major.
A13: mobility | B13: L3 bar → condition, exclusive within an axis | C13: Below the bar, nothing | D13: WFRP Prone/Entangled · Lancer Immobilized/Slowed | E13: Nothing in the field uses an ablative pool for a CAPABILITY axis — 4 of 7 movement is meaningless.
A14: acuity | B14: L3 bar → named condition | C14: Optionally L7 table to pick which sense | D14: WFRP Blinded/Deafened · GURPS stunning | E14: Same capability-axis argument as mobility.
A15: composure | B15: L0 buffer + L6 convert at the cap | C15: An evaporating in-scene buffer, then a named durable thing | D15: Blades stress 0–9 → Trauma · Fate mental stress → consequence | E15: The buffer belongs to the Landing Component, never the Substrate.
A16: clarity | B16: L3 MOVING bar + L7 table draw | C16: The bar itself moves after each crossing | D16: Delta Green Breaking Point (resets to new SAN − POW) · CoC | E16: A MOVING bar is the best mechanism found for having thresholds without the all-in incentive.
A17: will | B17: L9 HARDEN + L3 bar | C17: Resisting notches you toward immunity; failing notches you toward collapse | D17: Unknown Armies hardened/failed notches · DG Adaptation | E17: The mental block wants a two-signed axis the physical block does not. No physical system makes you harder to injure by injuring you; every serious mental system does.
A18: regard | B18: L10 land on a CONNECTION | C18: Never on the target Entity. Adjusts the HOLDER's stance, per participant | D18: Exalted 3e Intimacies · Delta Green Bonds | E18: Exalted: nothing is possible without exploiting an Intimacy. Landing must be able to REJECT a packet for lack of a Connection — and the rejection must be a Record, not a silent drop.
A19: standing | B19: L11 bank and discharge | C19: Accumulate; convert at a bar into a discrete level; carry the remainder | D19: Ars Magica Reputation (10 pts = +1 level) · Blades Heat→Wanted | E19: Ars Magica: a bad reputation is eroded only by growing a good one, never by subtraction.
... A21: essence | B21: L8 + L3 at zero | C21: The axis you never get back | D21: Ars Magica Warping · Vampire Humanity · DG POW loss | E21: Needs an explicit restoration path.
A23: ELEVEN MODELS EXIST (see lists-research.md §4): L0 evaporate · L1 pool · L2 track · L3 bar→condition · L4 phrase in a graded slot · L5 clock · L6 convert to another axis · L7 table draw · L8 scalar edit · L9 harden · L10 land on a Relationship · L11 bank and discharge.
A25: CONSIDERED AND REJECTED
A26: ONE AXIS, TWO MODELS BY MAGNITUDE | E26: THE HAZARD TO DECIDE. If vitality lands as a pool below a bar and a condition above it, the answer depends on HOW the total was assembled — which the packet no longer knows. Either Landing reads only the packet (one contributor-reading per Dimension) or it must be handed the contributor list, which is a SUBSTRATE FINDING. Lancer has an open issue on exactly this.
A27: assume health | E27: REJECT: the Substrate ships no Resources. Health is one answer among several.
A28: freeform phrase for everything | D28: Blades harm | E28: ARGUE: L4 is not machine-readable, so the Fold cannot reason about "Broken Leg". A phrase-returning Landing needs a Person Decider (rule 21); a table-returning one can be Auto.

Sheet L26 Listener condition forms
A1: L26 · Listener condition forms
A2: PENDING · research-seeded Aug 2026
A3: The closed set of things a Listener may watch. STATE, NEVER VERBS — "is this now true", never "did that just happen". Declared as data, evaluated at R-1400, produces Verbs pinned to a LATER Moment.
A4: MAGIC'S STATE-BASED ACTIONS ARE THE PROOF THIS WORKS AT SCALE. Rule 704.4: they "pay no attention to what happens during the resolution of a spell or ability" — a creature whose toughness dips to 0 mid-resolution and recovers SURVIVES. Only the state at the check point exists.
A6: Condition form | B6: Example | C6: Confidence | D6: Notes
A7: a Verb was just used | B7: "whenever someone attacks" | C7: — | D7: NOT a form. Listeners watch state. This is what the Resolution-Record form is for. | E7: ← example, not data
A8: a value crosses a bar | B8: vitality Resource ≤ 0 | C8: HIGH | D8: The workhorse. MTG state-based actions are almost entirely this.
A9: a value compares to another value | B9: my standing < theirs | C9: HIGH
A10: an Entity holds a State | B10: is prone | C10: HIGH
A11: an Entity holds a Tag (optionally magnitude ≥ N) | B11: has Flammable · has Hardness ≥ 3 | C11: HIGH | D11: Reads membership only. Must never be read as "this modifier applies" — that is the Righteous Fire failure.
A12: a set is non-empty, or has size N | B12: hostiles within reach ≥ 3 | C12: MEDIUM | D12: Depends on Place for "within reach".
A13: a Resolution Record exists matching a shape | B13: my vitality was restored by a source that is not me | C13: HIGH | D13: How reflection and retribution work without watching events. It IS state — the Record is a durable fact in the Ledger. Also the ONLY way to express "when you are healed by another", which is a real authoring need.
A14: a Moment of a named kind has occurred | B14: start of my turn | C14: HIGH | D14: Depends on L32.
A16: THREE BLANKS THAT MUST BE FILLED HERE, NOT LATER — and research now proposes all three. (1) DEPTH LIMIT: 32. (2) AT THE LIMIT: halt without applying, and WRITE A RECORD. (3) ORDER: (class, layer, component_id, listener_id, target_entity_id).
A18: CONSIDERED AND REJECTED
A19: depth limit: none, run to a fixpoint | D19: REJECT. MTG does this — it runs SBAs to a fixpoint and handles genuine loops with a SOCIAL rule (the game is a draw). We have no table to appeal to, so we need the counter MTG does not.
A20: depth limit: 32 | C20: PROPOSED | D20: SQL Server nested triggers settled on 32 twenty years ago and nobody has argued with it. High enough that no legitimate design reaches it, low enough to catch a runaway in milliseconds.
A21: at the limit: roll back | D21: REJECT: the Ledger is append-only. Rolling back is not available.
A22: at the limit: silently drop | D22: REJECT: invisible. Hearthstone does this and it is a known source of unexplainable board states.
A23: at the limit: halt without applying, write a Record | C23: PROPOSED | D23: Makes it a debuggable finding rather than a mystery. The honest version of "if you can violate it silently, the gate is missing."
A24: ordering by a global priority number | D24: REJECT. Drools salience is deterministic but NOT STABLE under rule-set edits — adding one rule changes the order of unrelated rules. Our sort key must be composed only of values that do not move when unrelated content is added.
A25: ordering: semantic class first, then the stable key | C25: PROPOSED | D25: Yu-Gi-Oh SEGOC is the only fully specified simultaneous-trigger ordering in any game, and its structure is a priority CLASSIFICATION first, then a declared tiebreak. Ours is currently layer-first; the finding is that the first key should be semantic.
A26: registration order | D26: REJECT: get it wrong and the same Ledger folds differently on two machines.

Sheet L27 Sockets
A1: L27 · Sockets
A2: PENDING · BLOCKING · three, Aug 2026
A3: Holes the Substrate declares and cannot fill. Exactly one occupant each, never zero, never two. A Bundle with an empty Socket must fail to load.
A4: THREE. Time and Budget moved into the Substrate in Aug 2026. Occupants are FROZEN PER SETTING — changing one makes a different Setting.
A6: Socket | B6: Vocabulary it publishes (Substrate) | C6: Behaviour it owns (occupant) | D6: Without it | E6: Notes
A7: Time | B7: Moment kinds: start of turn, end of round | C7: Which Moments exist, order, participant set | D7: Nothing can be pinned | E7: RETIRED as a Socket — now Substrate. Kept here as the worked example of the shape. | F7: ← example, not data
A8: Place | B8: How position and scope are named: here, near, within, containment. What Scale means for a part of a whole. | C8: What a place is and how distance works | D8: Nothing has a location, so nothing can be area-scoped, and nothing knows the door belongs to the ship | E8: SETTLED as a Socket. Not because distances differ — because a game about insects, a game about galaxies, one where everyone teleports and one in a 5-dimensional astral sea are not one game with different numbers.
A9: Resolution | B9: That an attempt returns a signed magnitude, AND the distribution it is drawn from | C9: How the magnitude is produced — dice, cards, deck, auction | D9: No attempt produces a number | E9: May be ONE occupant with dials. Dials pinned at Setting creation, never toggled live, or the fold stops being reproducible. The published-distribution clause is decidable now (rule 19) even though the formula is open.
A10: Landing | B10: What persistent state each Dimension may address (= L25, fourteen rows) | C10: How a landed vector becomes persistent state | D10: Vectors arrive and nothing happens | E10: Research (lists-research.md §4) says this is a PIPELINE, not one step: buffer -> convert -> name. The buffer belongs to the occupant and is never durable.
A12: THREE IS THE TARGET AND THE CEILING. Every Socket is a permanent dependency for every Component ever written AND a hole in the documentation. A capability belongs here only if the Substrate cannot function without it AND freezing one answer would make a whole class of Setting impossible.
A14: CONSIDERED AND REJECTED
A15: Time | E15: RETIRED Aug 2026 -> Substrate. A Socket is a hole in the explanation, not just the code; every worked example had to caveat itself. Coarser clocks are Components, added alongside.
A16: Budget | E16: RETIRED Aug 2026 -> Substrate (doubloon + cost shape). Allowance is base Ruleset.
A17: Progression | E17: REJECT: an ordinary Component. The Substrate runs fine with no advancement at all.
A18: Inventory | E18: REJECT: Entities and Relationships already express carrying.

Sheet L28 Economy
A1: L28 · Economy
A2: SETTLED IN PRINCIPLE · Aug 2026
A3: The atomic unit a cost is denominated in, and the shape of a cost. Substrate, because every ability ever written depends on both.
A4: ONE UNIT. NO DENOMINATIONS. NOTHING EVER DIVIDES. If a second unit is ever added it is NEVER convertible with the first.
A6: Item | B6: Decision | C6: Status | D6: Why | E6: Notes
A7: gold | B7: currency | C7: — | D7: — | E7: NOT this list. Money is a Resource in a Component. | F7: ← example, not data
A8: doubloon | B8: The one atomic Economy Unit. Integer, 64-bit. | C8: SETTLED | D8: Content is authored and folded in doubloons. Width chosen deliberately too wide — a currency range is as permanent as its meaning. | E8: Working name. Renaming is free later: one Substrate word, no arithmetic attached.
A9: denomination ladder | B9: CUT — no action / quick / free rungs | C9: SETTLED | D9: A size vocabulary beside a timing vocabulary made authoring roundabout. "reaction" is a WHEN; "action" is a HOW MUCH. | E9: The word "action" may not exist in the game at all. Fusing size and timing is what produced bonus action, which its designer publicly disowned.
A10: cost (field) | B10: A whole number of doubloons | C10: SETTLED | D10: How much it takes out of you. | E10: max(price)/allowance must stay well below 1 — see L28 notes.
A11: timing (field) | B11: A named member of the closed set — see L31 | C11: SETTLED | D11: When you may pay. | E11: Orthogonal to cost. A 10-doubloon reaction and a 40-doubloon reaction are both reactions.
A12: cap (field) | B12: How often, per Moment or per round | C12: SETTLED, optional | D12: Keeps frequency out of the timing name. | E12: Usually absent. More fields expected — this is the floor, not the ceiling.
A13: spend modes | B13: spent · committed | C13: PROPOSED | D13: Shape, not meaning, so Substrate. A repin must know whether a committed cost can be re-paid. | E13: Was three (spent/reserved/held); reserved and held collapsed.
A14: allowance | B14: How many doubloons per turn | C14: OPEN — base Ruleset | D14: A playtest number. Freezing it forever is a needless permanent bet. | E14: THAT an allowance exists and refreshes is Substrate; how big is not.
A15: second unit | B15: None for now | C15: OPEN | D15: Adding one later is free under additive-only. Adding one you do not need is permanent weight. | E15: If added: never convertible. Rate disagreement in an economy is a money printer, not a display bug.
A17: THE ATOM MAY BE FINE; THE PUBLISHED PRICE LIST MUST STAY SHORT. Every fine-grained action currency that failed (Exalted ticks, Rolemaster percentages, X-COM Time Units) failed on the price list, not the atom. Feng Shui has one price. PF2e: almost everything costs one.
A19: CONSIDERED AND REJECTED
A20: reaction | B20: Not a unit and not a size | C20: REJECTED | D20: It is a TIMING — doubloons spent during a Moment you do not own. | E20: That is why a 10-doubloon and a 40-doubloon reaction are both reactions.
A21: attention | B21: Not a unit | C21: REJECTED | D21: It is doubloons in the committed spend mode. Concentration is effort you spent that stays spent.
A22: strain | B22: Not a unit | C22: REJECTED | D22: It accumulates rather than being spent, which makes it a Resource. Exhaustion is already a vigor push plus a Resource.
A23: bonus action | B23: Not a unit | C23: REJECTED | D23: A rule about how many, not a kind of thing spent.
A24: movement | B24: Not a unit | C24: REJECTED | D24: Doubloons spent on moving. If it is not, that is Place business.

Sheet L29 Capacities
A1: L29 · Attempt Domains and Dimensions
A2: SETTLED — August 2026
A3: The attempt Space is two layers. A DOMAIN is an outcome and stores no number; its DIMENSIONS are genuinely different routes to that outcome. The GM names the Domain; the player picks the route.
